Workbook

Sheet Summary
A1: Vivid Windows - Payroll Oct 16, 2026
A2: Deals closing Wed Sep 30 - Tue Oct 6, 2026, plus released holds, summer weekly bonus for September and change-order true-ups on commission. Left out of every figure here: Vivid Adder, Recruiting bonus and Override - see the Excluded tab.
A4: Pay run | B4: Person | C4: Team | D4: Role | E4: Setter commission | F4: Closer commission | G4: Commission | H4: Summer bonus | I4: Change orders | J4: Adjustments | K4: Total | L4: Held back (not paid)
A5: 2026-10-16 | B5: Carl Crosland | C5: Northern Utah | D5: Sales Consultant | E5: 2196.3 | F5: 3953.34 | G5: =E5+F5 -> 6149.64 | H5: =SUMIFS(Accounts!$I:$I,Accounts!$A:$A,$B5,Accounts!$B:$B,"Summer bonus") -> 3100.16 | I5: =SUMIFS(Accounts!$I:$I,Accounts!$A:$A,$B5,Accounts!$B:$B,"Change order") -> -481.3 | J5: =SUMIFS(Adjustments!$D:$D,Adjustments!$A:$A,$B5) -> 0 | K5: =G5+H5+I5+J5 -> 8768.5 | L5: =SUMIFS(Withheld!$J:$J,Withheld!$A:$A,$B5) -> 0
A6: 2026-10-16 | B6: Nathan Lewis | C6: Northern California | D6: Sales Consultant | E6: 0 | F6: 4049.1 | G6: =E6+F6 -> 4049.1 | H6: =SUMIFS(Accounts!$I:$I,Accounts!$A:$A,$B6,Accounts!$B:$B,"Summer bonus") -> 0 | I6: =SUMIFS(Accounts!$I:$I,Accounts!$A:$A,$B6,Accounts!$B:$B,"Change order") -> -1976.76 | J6: =SUMIFS(Adjustments!$D:$D,Adjustments!$A:$A,$B6) -> 0 | K6: =G6+H6+I6+J6 -> 2072.34 | L6: =SUMIFS(Withheld!$J:$J,Withheld!$A:$A,$B6) -> 0
A7: 2026-10-16 | B7: Jordan Naylor | C7: Southern Utah | D7: Sales Consultant | E7: 0 | F7: 4868.37 | G7: =E7+F7 -> 4868.37 | H7: =SUMIFS(Accounts!$I:$I,Accounts!$A:$A,$B7,Accounts!$B:$B,"Summer bonus") -> 0 | I7: =SUMIFS(Accounts!$I:$I,Accounts!$A:$A,$B7,Accounts!$B:$B,"Change order") -> -1207.98 | J7: =SUMIFS(Adjustments!$D:$D,Adjustments!$A:$A,$B7) -> 0 | K7: =G7+H7+I7+J7 -> 3660.39 | L7: =SUMIFS(Withheld!$J:$J,Withheld!$A:$A,$B7) -> 0
A8: 2026-10-16 | B8: Brian Gwyn | C8: Eastern Idaho | D8: Sales Consultant | E8: 2876.55 | F8: 5177.79 | G8: =E8+F8 -> 8054.34 | H8: =SUMIFS(Accounts!$I:$I,Accounts!$A:$A,$B8,Accounts!$B:$B,"Summer bonus") -> 0 | I8: =SUMIFS(Accounts!$I:$I,Accounts!$A:$A,$B8,Accounts!$B:$B,"Change order") -> -359.94 | J8: =SUMIFS(Adjustments!$D:$D,Adjustments!$A:$A,$B8) -> 0 | K8: =G8+H8+I8+J8 -> 7694.4 | L8: =SUMIFS(Withheld!$J:$J,Withheld!$A:$A,$B8) -> 3661.02
A9: 2026-10-16 | B9: Ryan Kelsey | C9: Northern California | D9: Sales Consultant | E9: 2150.15 | F9: 3870.27 | G9: =E9+F9 -> 6020.42 | H9: =SUMIFS(Accounts!$I:$I,Accounts!$A:$A,$B9,Accounts!$B:$B,"Summer bonus") -> 1319.88 | I9: =SUMIFS(Accounts!$I:$I,Accounts!$A:$A,$B9,Accounts!$B:$B,"Change order") -> 0 | J9: =SUMIFS(Adjustments!$D:$D,Adjustments!$A:$A,$B9) -> 0 | K9: =G9+H9+I9+J9 -> 7340.3 | L9: =SUMIFS(Withheld!$J:$J,Withheld!$A:$A,$B9) -> 0
A10: 2026-10-16 | B10: Nick Brown | C10: Eastern Idaho | D10: Sales Consultant | E10: 0 | F10: 3381.66 | G10: =E10+F10 -> 3381.66 | H10: =SUMIFS(Accounts!$I:$I,Accounts!$A:$A,$B10,Accounts!$B:$B,"Summer bonus") -> 2521.58 | I10: =SUMIFS(Accounts!$I:$I,Accounts!$A:$A,$B10,Accounts!$B:$B,"Change order") -> 0 | J10: =SUMIFS(Adjustments!$D:$D,Adjustments!$A:$A,$B10) -> 0 | K10: =G10+H10+I10+J10 -> 5903.24 | L10: =SUMIFS(Withheld!$J:$J,Withheld!$A:$A,$B10) -> 0
A11: 2026-10-16 | B11: Brandon Simpson | C11: Eastern Idaho | D11: Sales Consultant | E11: 759.45 | F11: 0 | G11: =E11+F11 -> 759.45 | H11: =SUMIFS(Accounts!$I:$I,Accounts!$A:$A,$B11,Accounts!$B:$B,"Summer bonus") -> 3969.06 | I11: =SUMIFS(Accounts!$I:$I,Accounts!$A:$A,$B11,Accounts!$B:$B,"Change order") -> 0 | J11: =SUMIFS(Adjustments!$D:$D,Adjustments!$A:$A,$B11) -> 0 | K11: =G11+H11+I11+J11 -> 4728.51 | L11: =SUMIFS(Withheld!$J:$J,Withheld!$A:$A,$B11) -> 0
A12: 2026-10-16 | B12: Shawn Harding | C12: Northern Utah | D12: Sales Consultant | E12: 1072.8 | F12: 0 | G12: =E12+F12 -> 1072.8 | H12: =SUMIFS(Accounts!$I:$I,Accounts!$A:$A,$B12,Accounts!$B:$B,"Summer bonus") -> 3320 | I12: =SUMIFS(Accounts!$I:$I,Accounts!$A:$A,$B12,Accounts!$B:$B,"Change order") -> 0 | J12: =SUMIFS(Adjustments!$D:$D,Adjustments!$A:$A,$B12) -> 0 | K12: =G12+H12+I12+J12 -> 4392.8 | L12: =SUMIFS(Withheld!$J:$J,Withheld!$A:$A,$B12) -> 0
A13: 2026-10-16 | B13: Todd Hess | C13: Northern Utah | D13: Sales Consultant | E13: 0 | F13: 1931.04 | G13: =E13+F13 -> 1931.04 | H13: =SUMIFS(Accounts!$I:$I,Accounts!$A:$A,$B13,Accounts!$B:$B,"Summer bonus") -> 0 | I13: =SUMIFS(Accounts!$I:$I,Accounts!$A:$A,$B13,Accounts!$B:$B,"Change order") -> 0 | J13: =SUMIFS(Adjustments!$D:$D,Adjustments!$A:$A,$B13) -> 0 | K13: =G13+H13+I13+J13 -> 1931.04 | L13: =SUMIFS(Withheld!$J:$J,Withheld!$A:$A,$B13) -> 0
A14: 2026-10-16 | B14: Kimberly Simmerman | C14: Southern Utah | D14: Sales Consultant | E14: 1169.75 | F14: 0 | G14: =E14+F14 -> 1169.75 | H14: =SUMIFS(Accounts!$I:$I,Accounts!$A:$A,$B14,Accounts!$B:$B,"Summer bonus") -> 2151.72 | I14: =SUMIFS(Accounts!$I:$I,Accounts!$A:$A,$B14,Accounts!$B:$B,"Change order") -> 0 | J14: =SUMIFS(Adjustments!$D:$D,Adjustments!$A:$A,$B14) -> 0 | K14: =G14+H14+I14+J14 -> 3321.47 | L14: =SUMIFS(Withheld!$J:$J,Withheld!$A:$A,$B14) -> 0
A15: 2026-10-16 | B15: Chase Merrell | C15: Southern Utah | D15: Sales Consultant | E15: 0 | F15: 0 | G15: =E15+F15 -> 0 | H15: =SUMIFS(Accounts!$I:$I,Accounts!$A:$A,$B15,Accounts!$B:$B,"Summer bonus") -> 2662.12 | I15: =SUMIFS(Accounts!$I:$I,Accounts!$A:$A,$B15,Accounts!$B:$B,"Change order") -> 0 | J15: =SUMIFS(Adjustments!$D:$D,Adjustments!$A:$A,$B15) -> 0 | K15: =G15+H15+I15+J15 -> 2662.12 | L15: =SUMIFS(Withheld!$J:$J,Withheld!$A:$A,$B15) -> 0
A16: 2026-10-16 | B16: Isabella Basanta | C16: Northern Utah | D16: Sales Consultant | E16: 176.7 | F16: 0 | G16: =E16+F16 -> 176.7 | H16: =SUMIFS(Accounts!$I:$I,Accounts!$A:$A,$B16,Accounts!$B:$B,"Summer bonus") -> 2232.12 | I16: =SUMIFS(Accounts!$I:$I,Accounts!$A:$A,$B16,Accounts!$B:$B,"Change order") -> 0 | J16: =SUMIFS(Adjustments!$D:$D,Adjustments!$A:$A,$B16) -> 0 | K16: =G16+H16+I16+J16 -> 2408.82 | L16: =SUMIFS(Withheld!$J:$J,Withheld!$A:$A,$B16) -> 0
... A31: 2026-10-16 | B31: Jonathan Jensen | C31: Southern Utah | D31: Sales Consultant | E31: 0 | F31: 0 | G31: =E31+F31 -> 0 | H31: =SUMIFS(Accounts!$I:$I,Accounts!$A:$A,$B31,Accounts!$B:$B,"Summer bonus") -> 0 | I31: =SUMIFS(Accounts!$I:$I,Accounts!$A:$A,$B31,Accounts!$B:$B,"Change order") -> -1976.76 | J31: =SUMIFS(Adjustments!$D:$D,Adjustments!$A:$A,$B31) -> 0 | K31: =G31+H31+I31+J31 -> -1976.76 | L31: =SUMIFS(Withheld!$J:$J,Withheld!$A:$A,$B31) -> 0
B32: TOTAL | E32: =SUM(E5:E31) -> 16064.8 | F32: =SUM(F5:F31) -> 28916.64 | G32: =SUM(G5:G31) -> 44981.44 | H32: =SUM(H5:H31) -> 28819.92 | I32: =SUM(I5:I31) -> -7540.18 | J32: =SUM(J5:J31) -> -412.5 | K32: =SUM(K5:K31) -> 65848.68 | L32: =SUM(L5:L31) -> 7754.18
B34: Dashboard total for this run before exclusions | K34: 244715.46
B35: Taken out (Excluded tab) | K35: =K34-K32 -> 178866.78
B36: People whose only pay this run was excluded are not listed; they appear on the Excluded tab.

Sheet Accounts
A1: Person | B1: Kind | C1: Earned as | D1: Account | E1: Team | F1: Closed | G1: Contract value | H1: Paid on | I1: Amount | J1: Note
A2: Carl Crosland | B2: Change order | C2: Setter commission | D2: TRACEY USCOLA / 217 W 5th N | E2: Northern Utah | F2: 2026-03-26 | G2: 4400 | H2: 4400 | I2: -481.3 | J2: Contract value moved after it was paid
A3: Carl Crosland | B3: Summer bonus | C3: Setter, +4% | D3: Mark Earnhardt / 1 Starwood Dr | E3: Northern Utah | F3: 2026-09-14 | G3: 20821 | H3: 20821 | I3: 832.84 | J3: 3 deals set in the week of Sep 13, 2026
A4: Carl Crosland | B4: Summer bonus | C4: Setter, +4% | D4: Bob Oldenburg / 3771 Sparrow Dr | E4: Northern Utah | F4: 2026-09-15 | G4: 12757 | H4: 12757 | I4: 510.28 | J4: 3 deals set in the week of Sep 13, 2026
A5: Carl Crosland | B5: Commission | C5: Self-gen | D5: Laron Crosland / 2217 W Windchime Dr | E5: Northern Utah | F5: 2026-09-19 | G5: 43926 | H5: 43926 | I5: 6149.64 | J5: Set and closed by the same person · setter $2,196.30 + closer $3,953.34 · Released from an earlier run · Released from an earlier run
A6: Carl Crosland | B6: Summer bonus | C6: Setter, +4% | D6: Laron Crosland / 2217 W Windchime Dr | E6: Northern Utah | F6: 2026-09-19 | G6: 43926 | H6: 43926 | I6: 1757.04 | J6: 3 deals set in the week of Sep 13, 2026
A7: Nathan Lewis | B7: Change order | C7: Closer commission | D7: Amanda Morning Star / 120 Riverview 3 E | E7: Southern Utah | F7: 2026-07-21 | G7: 21964 | H7: 0 | I7: -1976.76 | J7: Contract value moved after it was paid
A8: Nathan Lewis | B8: Commission | C8: Closer | D8: Brett & Jennie Lefevre / 2817 S 2460 E | E8: Southern Utah | F8: 2026-09-26 | G8: 17811 | H8: 17811 | I8: 1602.99 | J8: Released from an earlier run
A9: Nathan Lewis | B9: Commission | C9: Closer | D9: Tara & Vincent Turpin / 1109 Babcock Blvd | E9: Southern Utah | F9: 2026-10-05 | G9: 27179 | H9: 27179 | I9: 2446.11
A10: Jordan Naylor | B10: Change order | C10: Closer commission | D10: MARIA PALMER / 11394 E 25th Pl | E10: Southern Utah | F10: 2026-05-30 | G10: 13422 | H10: 0 | I10: -1207.98 | J10: Contract value moved after it was paid
A11: Jordan Naylor | B11: Commission | C11: Closer | D11: Darrell & Maggie Phillips / 2220 Pintura Dr | E11: Southern Utah | F11: 2026-09-09 | G11: 15902 | H11: 15902 | I11: 1431.18 | J11: Released from an earlier run
A12: Jordan Naylor | B12: Commission | C12: Closer | D12: Mical & Elaine Terry / 993 N 2075 East Cir | E12: Southern Utah | F12: 2026-10-01 | G12: 14796 | H12: 14796 | I12: 1331.64
A13: Jordan Naylor | B13: Commission | C13: Closer | D13: Gauge & Samantha Kevern / 1099 Cedar Knls S | E13: Southern Utah | F13: 2026-10-02 | G13: 23395 | H13: 23395 | I13: 2105.55
A14: Brian Gwyn | B14: Change order | C14: Self-gen | D14: Karri Holland / 920 W Elva St | E14: Eastern Idaho | F14: 2026-06-16 | G14: 2571 | H14: 0 | I14: -359.94 | J14: Set and closed by the same person · setter commission -$128.55 + closer commission -$231.39 · Contract value moved after it was paid
A15: Brian Gwyn | B15: Commission | C15: Self-gen | D15: Robert & Maria Becker / 2405 3rd Ave N | E15: Eastern Idaho | F15: 2026-09-30 | G15: 47530 | H15: 47530 | I15: 6654.2 | J15: Set and closed by the same person · setter $2,376.50 + closer $4,277.70
A16: Brian Gwyn | B16: Commission | C16: Self-gen | D16: Daniel & Jennie Sue Gutierrez / 1507 Ammon St | E16: Eastern Idaho | F16: 2026-10-05 | G16: 10001 | H16: 10001 | I16: 1400.14 | J16: Set and closed by the same person · setter $500.05 + closer $900.09
A17: Ryan Kelsey | B17: Commission | C17: Self-gen | D17: Lewis Disbrow / 2473 Pine St | E17: Northern California | F17: 2026-09-08 | G17: 43003 | H17: 43003 | I17: 6020.42 | J17: Set and closed by the same person · setter $2,150.15 + closer $3,870.27 · Released from an earlier run · Released from an earlier run
A18: Ryan Kelsey | B18: Summer bonus | C18: Setter, +2% | D18: Lewis Disbrow / 2473 Pine St | E18: Northern California | F18: 2026-09-08 | G18: 43003 | H18: 43003 | I18: 860.06 | J18: 2 deals set in the week of Sep 6, 2026
A19: Ryan Kelsey | B19: Summer bonus | C19: Setter, +2% | D19: Karen Tomajan / 623 Pasa Tiempo Ct | E19: Northern California | F19: 2026-09-12 | G19: 22991 | H19: 22991 | I19: 459.82 | J19: 2 deals set in the week of Sep 6, 2026
A20: Nick Brown | B20: Summer bonus | C20: Setter, +2% | D20: Shawna Williams / 2213 Pauline Dr | E20: Eastern Idaho | F20: 2026-09-09 | G20: 16955 | H20: 16955 | I20: 339.1 | J20: 2 deals set in the week of Sep 6, 2026
A21: Nick Brown | B21: Commission | C21: Closer | D21: Joy Hepworth / 131 Willard Ave | E21: Eastern Idaho | F21: 2026-09-10 | G21: 12935 | H21: 12935 | I21: 1164.15 | J21: Released from an earlier run
A22: Nick Brown | B22: Summer bonus | C22: Setter, +2% | D22: Robert Peraino / 3255 Humble Rd | E22: Eastern Idaho | F22: 2026-09-12 | G22: 10098 | H22: 10098 | I22: 201.96 | J22: 2 deals set in the week of Sep 6, 2026
A23: Nick Brown | B23: Summer bonus | C23: Setter, +4% | D23: Russell Simmons / 100 Sharon Dr | E23: Eastern Idaho | F23: 2026-09-23 | G23: 15055 | H23: 15055 | I23: 602.2 | J23: 3 deals set in the week of Sep 20, 2026
A24: Nick Brown | B24: Summer bonus | C24: Setter, +4% | D24: Kasey Morris / 1330 Country Home Ln | E24: Eastern Idaho | F24: 2026-09-24 | G24: 7603 | H24: 7603 | I24: 304.12 | J24: 3 deals set in the week of Sep 20, 2026
A25: Nick Brown | B25: Commission | C25: Closer | D25: Kali Dubose / 213 18th Ave NW | E25: Eastern Idaho | F25: 2026-09-25 | G25: 11832 | H25: 11832 | I25: 1064.88 | J25: Released from an earlier run
A26: Nick Brown | B26: Summer bonus | C26: Setter, +4% | D26: Brett Breaud / 1 Prospect Way | E26: Eastern Idaho | F26: 2026-09-26 | G26: 26855 | H26: 26855 | I26: 1074.2 | J26: 3 deals set in the week of Sep 20, 2026
A27: Nick Brown | B27: Commission | C27: Closer | D27: Clay Skinner / 297 Westview Dr | E27: Eastern Idaho | F27: 2026-10-06 | G27: 12807 | H27: 12807 | I27: 1152.63
A28: Brandon Simpson | B28: Summer bonus | C28: Setter, +4% | D28: Choti Skousen / 17 Marthas Ct | E28: Eastern Idaho | F28: 2026-09-08 | G28: 10997 | H28: 10997 | I28: 439.88 | J28: 6 deals set in the week of Sep 6, 2026
A29: Brandon Simpson | B29: Summer bonus | C29: Setter, +4% | D29: Gretchen Murray / 27 Canyon View Dr | E29: Eastern Idaho | F29: 2026-09-10 | G29: 15833 | H29: 15833 | I29: 633.32 | J29: 6 deals set in the week of Sep 6, 2026
A30: Brandon Simpson | B30: Summer bonus | C30: Setter, +4% | D30: Susan Quillen / 4600 Lerch Ln | E30: Eastern Idaho | F30: 2026-09-11 | G30: 8050 | H30: 8050 | I30: 322 | J30: 6 deals set in the week of Sep 6, 2026
A31: Brandon Simpson | B31: Summer bonus | C31: Setter, +4% | D31: Vicky Thorpe / 515 Utah Ave | E31: Eastern Idaho | F31: 2026-09-11 | G31: 7635 | H31: 0 | I31: 0 | J31: 6 deals set in the week of Sep 6, 2026
A32: Brandon Simpson | B32: Summer bonus | C32: Setter, +4% | D32: Mitchell Jesse / 7787 Bear Dr | E32: Eastern Idaho | F32: 2026-09-12 | G32: 19259 | H32: 19259 | I32: 770.36 | J32: 6 deals set in the week of Sep 6, 2026
A33: Brandon Simpson | B33: Summer bonus | C33: Setter, +4% | D33: Sandy Brown / 7875 Bear Dr | E33: Eastern Idaho | F33: 2026-09-12 | G33: 14318 | H33: 14318 | I33: 572.72 | J33: 6 deals set in the week of Sep 6, 2026
A34: Brandon Simpson | B34: Summer bonus | C34: Setter, +2% | D34: Mike Debolt / 311 24th St SW | E34: Eastern Idaho | F34: 2026-09-25 | G34: 10008 | H34: 10008 | I34: 200.16 | J34: 2 deals set in the week of Sep 20, 2026
A35: Brandon Simpson | B35: Summer bonus | C35: Setter, +2% | D35: Susette Schabarker / 423 31st St NW | E35: Eastern Idaho | F35: 2026-09-26 | G35: 18938 | H35: 18938 | I35: 378.76 | J35: 2 deals set in the week of Sep 20, 2026
A36: Brandon Simpson | B36: Summer bonus | C36: Setter, +2% | D36: Joseph Canete / 413 Van Buren Ave | E36: Eastern Idaho | F36: 2026-09-28 | G36: 17404 | H36: 17404 | I36: 348.08 | J36: 2 deals set in the week of Sep 27, 2026
A37: Brandon Simpson | B37: Commission | C37: Setter | D37: Melissa Shandley / 298 Washington Blvd | E37: Eastern Idaho | F37: 2026-09-30 | G37: 15189 | H37: 15189 | I37: 759.45
A38: Brandon Simpson | B38: Summer bonus | C38: Setter, +2% | D38: Melissa Shandley / 298 Washington Blvd | E38: Eastern Idaho | F38: 2026-09-30 | G38: 15189 | H38: 15189 | I38: 303.78 | J38: 2 deals set in the week of Sep 27, 2026
A39: Shawn Harding | B39: Summer bonus | C39: Setter, +4% | D39: Timothy Broadbrooks / 3472 Ayden Rd | E39: Northern Utah | F39: 2026-09-14 | G39: 20247 | H39: 20247 | I39: 809.88 | J39: 6 deals set in the week of Sep 13, 2026
A40: Shawn Harding | B40: Summer bonus | C40: Setter, +4% | D40: Chad Guymon / 3755 Pioneer Park Dr | E40: Northern Utah | F40: 2026-09-15 | G40: 16393 | H40: 16393 | I40: 655.72 | J40: 6 deals set in the week of Sep 13, 2026
...

Sheet Adjustments
A1: Person | B1: Type | C1: Reason | D1: Amount
A2: Blake Holmes | B2: Chargeback | C2: Teema McIntosh / 6819 Red Cloud Trl - Cancelled after the 3-day ROC window | D2: -412.5
A3: TOTAL | D3: =SUM(D2:D2) -> -412.5

Sheet Withheld
A1: Person | B1: Account | C1: Team | D1: Closed | E1: Leg | F1: Reason | G1: Held since | H1: Placed by | I1: Would have paid in | J1: Withheld
A2: Brian Gwyn | B2: Matt & Shauna Bevan / 272 Saddle Dr | C2: Eastern Idaho | D2: 2026-10-09 | E2: Closer | F2: Customer financing not approved | G2: 2026-10-15 | H2: The CRM | I2: Oct 23, 2026 | J2: 3661.02
A3: Lane Coffey | B3: Matt & Shauna Bevan / 272 Saddle Dr | C3: Eastern Idaho | D3: 2026-10-09 | E3: Setter | F3: Customer financing not approved | G3: 2026-10-15 | H3: The CRM | I3: Oct 23, 2026 | J3: 2033.9
A4: Kerrigan Simpson | B4: Tammy Buckley / 31 Jefferson Dr | C4: Northern Utah | D4: 2026-09-22 | E4: Closer | F4: Customer financing not approved | G4: 2026-09-29 | H4: The CRM | I4: Oct 2, 2026 | J4: 1323.81
A5: Camille Gerritsen | B5: Tammy Buckley / 31 Jefferson Dr | C5: Northern Utah | D5: 2026-09-22 | E5: Setter | F5: Customer financing not approved | G5: 2026-09-29 | H5: The CRM | I5: Oct 2, 2026 | J5: 735.45
A6: Brandon Simpson | B6: Steven Nelson / 132 Bearlake Dr | C6: Eastern Idaho | D6: 2026-09-04 | E6: Setter | F6: Customer financing not approved | G6: 2026-09-16 | H6: Abipsha Joshi | I6: Sep 18, 2026 | J6: 0
A7: Brian Gwyn | B7: Steven Nelson / 132 Bearlake Dr | C7: Eastern Idaho | D7: 2026-09-04 | E7: Closer | F7: Customer financing not approved | G7: 2026-09-16 | H7: Abipsha Joshi | I7: Sep 18, 2026 | J7: 0
A8: Not payable - every leg on hold across the ledger, not only this run | J8: =SUM(J2:J7) -> 7754.18

Sheet Excluded
A1: Left out of the Oct 16, 2026 payroll
A2: What the dashboard would have paid on this run but this report does not. Nothing here is in the Summary.
A4: Person | B4: Recruiting (Sep) | C4: Override (Sep) | D4: Vivid Adder (Q2) | E4: Recruiting / Override change orders | F4: Excluded total
A5: JJ Gurney | B5: 3696.29 | C5: 77726.92 | D5: 3000 | E5: -2372.21 | F5: =SUM(B5:E5) -> 82051
A6: Carl Crosland | B6: 6590.93 | C6: 19517.8 | D6: 500 | E6: -457.23 | F6: =SUM(B6:E6) -> 26151.5
A7: Nathan Lewis | B7: 1724.5 | C7: 0 | D7: 29500 | E7: 0 | F7: =SUM(B7:E7) -> 31224.5
A8: Jordan Naylor | B8: 0 | C8: 16946.8 | D8: -500 | E8: -1415.44 | F8: =SUM(B8:E8) -> 15031.36
A9: Brian Gwyn | B9: 49.41 | C9: 0 | D9: 0 | E9: 0 | F9: =SUM(B9:E9) -> 49.41
A10: Tyler Mickelsen | B10: 7160.34 | C10: 0 | D10: 0 | E10: -299.54 | F10: =SUM(B10:E10) -> 6860.8
A11: Nick Brown | B11: 811.27 | C11: 0 | D11: 0 | E11: 0 | F11: =SUM(B11:E11) -> 811.27
A12: Mavryck Holmgren | B12: 5687.68 | C12: 0 | D12: 0 | E12: 0 | F12: =SUM(B12:E12) -> 5687.68
A13: Todd Hess | B13: 690.28 | C13: 0 | D13: 1500 | E13: 0 | F13: =SUM(B13:E13) -> 2190.28
A14: Brady Bethers | B14: 0 | C14: 0 | D14: 2500 | E14: 0 | F14: =SUM(B14:E14) -> 2500
A15: Colter Busk | B15: 1042.02 | C15: 0 | D15: 0 | E15: 0 | F15: =SUM(B15:E15) -> 1042.02
A16: Brock Morrison | B16: 2283.57 | C16: 0 | D16: 0 | E16: -122.01 | F16: =SUM(B16:E16) -> 2161.56
... A24: Scott Heer | B24: 148.23 | C24: 0 | D24: 0 | E24: 0 | F24: =SUM(B24:E24) -> 148.23
A25: TOTAL | B25: =SUM(B5:B24) -> 31841.72 | C25: =SUM(C5:C24) -> 114191.52 | D25: =SUM(D5:D24) -> 37500 | E25: =SUM(E5:E24) -> -4666.43 | F25: =SUM(F5:F24) -> 178866.81
A27: Excluded change-order lines (recruiting and override true-ups)
A28: Person | B28: Earned as | C28: Account | D28: Closed | E28: Amount
A29: JJ Gurney | B29: Override Northern Utah | C29: TRACEY USCOLA / 217 W 5th N | D29: 2026-03-26 | E29: -385.04
A30: JJ Gurney | B30: Recruiting L1 on Jordan Naylor | C30: MARIA PALMER / 11394 E 25th Pl | D30: 2026-05-30 | E30: -100.66
A31: JJ Gurney | B31: Recruiting L1 on Colter Busk | C31: MARIA PALMER / 11394 E 25th Pl | D31: 2026-05-30 | E31: -100.66
A32: JJ Gurney | B32: Override Southern Utah | C32: MARIA PALMER / 11394 E 25th Pl | D32: 2026-05-30 | E32: -536.88
A33: JJ Gurney | B33: Self-gen | C33: Karri Holland / 920 W Elva St | D33: 2026-06-16 | E33: -205.68
A34: JJ Gurney | B34: Recruiting L1 on Jonathan Jensen | C34: Amanda Morning Star / 120 Riverview 3 E | D34: 2026-07-21 | E34: -164.73
A35: JJ Gurney | B35: Override Southern Utah | C35: Amanda Morning Star / 120 Riverview 3 E | D35: 2026-07-21 | E35: -878.56
A36: Carl Crosland | B36: Recruiting L1 on Dane Covington | C36: TRACEY USCOLA / 217 W 5th N | D36: 2026-03-26 | E36: -72.19
A37: Carl Crosland | B37: Override Northern Utah | C37: TRACEY USCOLA / 217 W 5th N | D37: 2026-03-26 | E37: -385.04
A38: Jordan Naylor | B38: Override Southern Utah | C38: MARIA PALMER / 11394 E 25th Pl | D38: 2026-05-30 | E38: -536.88
A39: Jordan Naylor | B39: Override Southern Utah | C39: Amanda Morning Star / 120 Riverview 3 E | D39: 2026-07-21 | E39: -878.56
A40: Tyler Mickelsen | B40: Recruiting L2 on Dane Covington | C40: TRACEY USCOLA / 217 W 5th N | D40: 2026-03-26 | E40: -24.06
... A46: Brock Morrison | B46: Recruiting L2 on Jonathan Jensen | C46: Amanda Morning Star / 120 Riverview 3 E | D46: 2026-07-21 | E46: -54.91
A48: Excluded Vivid Adder lines
A49: Person | B49: Type | C49: Reason | D49: Amount
A50: Boden Black | B50: Vivid Adder | C50: Vivid Adder - Q2 2026 - 2 adders at $500 on 2 deals closed Apr 1, 2026 - Jun 30, 2026 | D50: 1000
A51: Brady Bethers | B51: Vivid Adder | C51: Vivid Adder - Q2 2026 - 5 adders at $500 on 2 deals closed Apr 1, 2026 - Jun 30, 2026 | D51: 2500
A52: Carl Crosland | B52: Vivid Adder | C52: Vivid Adder - Q2 2026 - 1 adder at $500 on 1 deal closed Apr 1, 2026 - Jun 30, 2026 | D52: 500
A53: JJ Gurney | B53: Vivid Adder | C53: Vivid Adder - Q2 2026 - 6 adders at $500 on 3 deals closed Apr 1, 2026 - Jun 30, 2026 | D53: 3000
A54: Jordan Naylor | B54: Vivid Adder | C54: Vivid Adder - Q2 2026 - 1 adder taken back at $500 on 1 deal closed Apr 1, 2026 - Jun 30, 2026 | D54: -500
A55: Nathan Lewis | B55: Vivid Adder | C55: Vivid Adder - Q2 2026 - 59 adders at $500 on 18 deals closed Apr 1, 2026 - Jun 30, 2026 | D55: 29500
...

Sheet Carl Crosland
A1: Carl Crosland | B1: Oct 16, 2026 run
A2: Northern Utah - Sales Consultant
A4: Account | B4: Team | C4: Closed | D4: Earned as | E4: Contract value | F4: Paid on | G4: Amount | H4: Note
A5: TRACEY USCOLA / 217 W 5th N | B5: Northern Utah | C5: 2026-03-26 | D5: Change order - Setter commission | E5: 4400 | F5: 4400 | G5: -481.3 | H5: Contract value moved after it was paid
A6: Mark Earnhardt / 1 Starwood Dr | B6: Northern Utah | C6: 2026-09-14 | D6: Summer bonus - Setter, +4% | E6: 20821 | F6: 20821 | G6: 832.84 | H6: 3 deals set in the week of Sep 13, 2026
A7: Bob Oldenburg / 3771 Sparrow Dr | B7: Northern Utah | C7: 2026-09-15 | D7: Summer bonus - Setter, +4% | E7: 12757 | F7: 12757 | G7: 510.28 | H7: 3 deals set in the week of Sep 13, 2026
A8: Laron Crosland / 2217 W Windchime Dr | B8: Northern Utah | C8: 2026-09-19 | D8: Commission - Self-gen | E8: 43926 | F8: 43926 | G8: 6149.64 | H8: Set and closed by the same person · setter $2,196.30 + closer $3,953.34 · Released from an earlier run · Released from an earlier run
A9: Laron Crosland / 2217 W Windchime Dr | B9: Northern Utah | C9: 2026-09-19 | D9: Summer bonus - Setter, +4% | E9: 43926 | F9: 43926 | G9: 1757.04 | H9: 3 deals set in the week of Sep 13, 2026
A10: Accounts | G10: =SUM(G5:G9) -> 8768.5
A11: Adjustments | G11: =SUMIFS(Adjustments!$D:$D,Adjustments!$A:$A,"Carl Crosland") -> 0
A12: Paid this run | G12: =G10+G11 -> 8768.5

Sheet Nathan Lewis
A1: Nathan Lewis | B1: Oct 16, 2026 run
A2: Northern California - Sales Consultant
A4: Account | B4: Team | C4: Closed | D4: Earned as | E4: Contract value | F4: Paid on | G4: Amount | H4: Note
A5: Amanda Morning Star / 120 Riverview 3 E | B5: Southern Utah | C5: 2026-07-21 | D5: Change order - Closer commission | E5: 21964 | F5: 0 | G5: -1976.76 | H5: Contract value moved after it was paid
A6: Brett & Jennie Lefevre / 2817 S 2460 E | B6: Southern Utah | C6: 2026-09-26 | D6: Commission - Closer | E6: 17811 | F6: 17811 | G6: 1602.99 | H6: Released from an earlier run
A7: Tara & Vincent Turpin / 1109 Babcock Blvd | B7: Southern Utah | C7: 2026-10-05 | D7: Commission - Closer | E7: 27179 | F7: 27179 | G7: 2446.11
A8: Accounts | G8: =SUM(G5:G7) -> 2072.34
A9: Adjustments | G9: =SUMIFS(Adjustments!$D:$D,Adjustments!$A:$A,"Nathan Lewis") -> 0
A10: Paid this run | G10: =G8+G9 -> 2072.34

Sheet Jordan Naylor
A1: Jordan Naylor | B1: Oct 16, 2026 run
A2: Southern Utah - Sales Consultant
A4: Account | B4: Team | C4: Closed | D4: Earned as | E4: Contract value | F4: Paid on | G4: Amount | H4: Note
A5: MARIA PALMER / 11394 E 25th Pl | B5: Southern Utah | C5: 2026-05-30 | D5: Change order - Closer commission | E5: 13422 | F5: 0 | G5: -1207.98 | H5: Contract value moved after it was paid
A6: Darrell & Maggie Phillips / 2220 Pintura Dr | B6: Southern Utah | C6: 2026-09-09 | D6: Commission - Closer | E6: 15902 | F6: 15902 | G6: 1431.18 | H6: Released from an earlier run
A7: Mical & Elaine Terry / 993 N 2075 East Cir | B7: Southern Utah | C7: 2026-10-01 | D7: Commission - Closer | E7: 14796 | F7: 14796 | G7: 1331.64
A8: Gauge & Samantha Kevern / 1099 Cedar Knls S | B8: Southern Utah | C8: 2026-10-02 | D8: Commission - Closer | E8: 23395 | F8: 23395 | G8: 2105.55
A9: Accounts | G9: =SUM(G5:G8) -> 3660.39
A10: Adjustments | G10: =SUMIFS(Adjustments!$D:$D,Adjustments!$A:$A,"Jordan Naylor") -> 0
A11: Paid this run | G11: =G9+G10 -> 3660.39

Sheet Brian Gwyn
A1: Brian Gwyn | B1: Oct 16, 2026 run
A2: Eastern Idaho - Sales Consultant
A4: Account | B4: Team | C4: Closed | D4: Earned as | E4: Contract value | F4: Paid on | G4: Amount | H4: Note
A5: Karri Holland / 920 W Elva St | B5: Eastern Idaho | C5: 2026-06-16 | D5: Change order - Self-gen | E5: 2571 | F5: 0 | G5: -359.94 | H5: Set and closed by the same person · setter commission -$128.55 + closer commission -$231.39 · Contract value moved after it was paid
A6: Robert & Maria Becker / 2405 3rd Ave N | B6: Eastern Idaho | C6: 2026-09-30 | D6: Commission - Self-gen | E6: 47530 | F6: 47530 | G6: 6654.2 | H6: Set and closed by the same person · setter $2,376.50 + closer $4,277.70
A7: Daniel & Jennie Sue Gutierrez / 1507 Ammon St | B7: Eastern Idaho | C7: 2026-10-05 | D7: Commission - Self-gen | E7: 10001 | F7: 10001 | G7: 1400.14 | H7: Set and closed by the same person · setter $500.05 + closer $900.09
A8: Accounts | G8: =SUM(G5:G7) -> 7694.4
A9: Adjustments | G9: =SUMIFS(Adjustments!$D:$D,Adjustments!$A:$A,"Brian Gwyn") -> 0
A10: Paid this run | G10: =G8+G9 -> 7694.4
A11: Held back - not paid
A12: Account | B12: Team | C12: Closed | D12: Leg | E12: Reason | F12: Held since | G12: Placed by | H12: Would have paid in | I12: Withheld
A13: Matt & Shauna Bevan / 272 Saddle Dr | B13: Eastern Idaho | C13: 2026-10-09 | D13: Closer | E13: Customer financing not approved | F13: 2026-10-15 | G13: The CRM | H13: Oct 23, 2026 | I13: 3661.02
A14: Steven Nelson / 132 Bearlake Dr | B14: Eastern Idaho | C14: 2026-09-04 | D14: Closer | E14: Customer financing not approved | F14: 2026-09-16 | G14: Abipsha Joshi | H14: Sep 18, 2026 | I14: 0

Sheet Ryan Kelsey
A1: Ryan Kelsey | B1: Oct 16, 2026 run
A2: Northern California - Sales Consultant
A4: Account | B4: Team | C4: Closed | D4: Earned as | E4: Contract value | F4: Paid on | G4: Amount | H4: Note
A5: Lewis Disbrow / 2473 Pine St | B5: Northern California | C5: 2026-09-08 | D5: Commission - Self-gen | E5: 43003 | F5: 43003 | G5: 6020.42 | H5: Set and closed by the same person · setter $2,150.15 + closer $3,870.27 · Released from an earlier run · Released from an earlier run
A6: Lewis Disbrow / 2473 Pine St | B6: Northern California | C6: 2026-09-08 | D6: Summer bonus - Setter, +2% | E6: 43003 | F6: 43003 | G6: 860.06 | H6: 2 deals set in the week of Sep 6, 2026
A7: Karen Tomajan / 623 Pasa Tiempo Ct | B7: Northern California | C7: 2026-09-12 | D7: Summer bonus - Setter, +2% | E7: 22991 | F7: 22991 | G7: 459.82 | H7: 2 deals set in the week of Sep 6, 2026
A8: Accounts | G8: =SUM(G5:G7) -> 7340.3
A9: Adjustments | G9: =SUMIFS(Adjustments!$D:$D,Adjustments!$A:$A,"Ryan Kelsey") -> 0
A10: Paid this run | G10: =G8+G9 -> 7340.3

Sheet Nick Brown
A1: Nick Brown | B1: Oct 16, 2026 run
A2: Eastern Idaho - Sales Consultant
A4: Account | B4: Team | C4: Closed | D4: Earned as | E4: Contract value | F4: Paid on | G4: Amount | H4: Note
A5: Shawna Williams / 2213 Pauline Dr | B5: Eastern Idaho | C5: 2026-09-09 | D5: Summer bonus - Setter, +2% | E5: 16955 | F5: 16955 | G5: 339.1 | H5: 2 deals set in the week of Sep 6, 2026
A6: Joy Hepworth / 131 Willard Ave | B6: Eastern Idaho | C6: 2026-09-10 | D6: Commission - Closer | E6: 12935 | F6: 12935 | G6: 1164.15 | H6: Released from an earlier run
A7: Robert Peraino / 3255 Humble Rd | B7: Eastern Idaho | C7: 2026-09-12 | D7: Summer bonus - Setter, +2% | E7: 10098 | F7: 10098 | G7: 201.96 | H7: 2 deals set in the week of Sep 6, 2026
A8: Russell Simmons / 100 Sharon Dr | B8: Eastern Idaho | C8: 2026-09-23 | D8: Summer bonus - Setter, +4% | E8: 15055 | F8: 15055 | G8: 602.2 | H8: 3 deals set in the week of Sep 20, 2026
A9: Kasey Morris / 1330 Country Home Ln | B9: Eastern Idaho | C9: 2026-09-24 | D9: Summer bonus - Setter, +4% | E9: 7603 | F9: 7603 | G9: 304.12 | H9: 3 deals set in the week of Sep 20, 2026
A10: Kali Dubose / 213 18th Ave NW | B10: Eastern Idaho | C10: 2026-09-25 | D10: Commission - Closer | E10: 11832 | F10: 11832 | G10: 1064.88 | H10: Released from an earlier run
A11: Brett Breaud / 1 Prospect Way | B11: Eastern Idaho | C11: 2026-09-26 | D11: Summer bonus - Setter, +4% | E11: 26855 | F11: 26855 | G11: 1074.2 | H11: 3 deals set in the week of Sep 20, 2026
A12: Clay Skinner / 297 Westview Dr | B12: Eastern Idaho | C12: 2026-10-06 | D12: Commission - Closer | E12: 12807 | F12: 12807 | G12: 1152.63
A13: Accounts | G13: =SUM(G5:G12) -> 5903.24
A14: Adjustments | G14: =SUMIFS(Adjustments!$D:$D,Adjustments!$A:$A,"Nick Brown") -> 0
A15: Paid this run | G15: =G13+G14 -> 5903.24

Sheet Brandon Simpson
A1: Brandon Simpson | B1: Oct 16, 2026 run
A2: Eastern Idaho - Sales Consultant
A4: Account | B4: Team | C4: Closed | D4: Earned as | E4: Contract value | F4: Paid on | G4: Amount | H4: Note
A5: Choti Skousen / 17 Marthas Ct | B5: Eastern Idaho | C5: 2026-09-08 | D5: Summer bonus - Setter, +4% | E5: 10997 | F5: 10997 | G5: 439.88 | H5: 6 deals set in the week of Sep 6, 2026
A6: Gretchen Murray / 27 Canyon View Dr | B6: Eastern Idaho | C6: 2026-09-10 | D6: Summer bonus - Setter, +4% | E6: 15833 | F6: 15833 | G6: 633.32 | H6: 6 deals set in the week of Sep 6, 2026
A7: Susan Quillen / 4600 Lerch Ln | B7: Eastern Idaho | C7: 2026-09-11 | D7: Summer bonus - Setter, +4% | E7: 8050 | F7: 8050 | G7: 322 | H7: 6 deals set in the week of Sep 6, 2026
A8: Vicky Thorpe / 515 Utah Ave | B8: Eastern Idaho | C8: 2026-09-11 | D8: Summer bonus - Setter, +4% | E8: 7635 | F8: 0 | G8: 0 | H8: 6 deals set in the week of Sep 6, 2026
A9: Mitchell Jesse / 7787 Bear Dr | B9: Eastern Idaho | C9: 2026-09-12 | D9: Summer bonus - Setter, +4% | E9: 19259 | F9: 19259 | G9: 770.36 | H9: 6 deals set in the week of Sep 6, 2026
A10: Sandy Brown / 7875 Bear Dr | B10: Eastern Idaho | C10: 2026-09-12 | D10: Summer bonus - Setter, +4% | E10: 14318 | F10: 14318 | G10: 572.72 | H10: 6 deals set in the week of Sep 6, 2026
A11: Mike Debolt / 311 24th St SW | B11: Eastern Idaho | C11: 2026-09-25 | D11: Summer bonus - Setter, +2% | E11: 10008 | F11: 10008 | G11: 200.16 | H11: 2 deals set in the week of Sep 20, 2026
A12: Susette Schabarker / 423 31st St NW | B12: Eastern Idaho | C12: 2026-09-26 | D12: Summer bonus - Setter, +2% | E12: 18938 | F12: 18938 | G12: 378.76 | H12: 2 deals set in the week of Sep 20, 2026
A13: Joseph Canete / 413 Van Buren Ave | B13: Eastern Idaho | C13: 2026-09-28 | D13: Summer bonus - Setter, +2% | E13: 17404 | F13: 17404 | G13: 348.08 | H13: 2 deals set in the week of Sep 27, 2026
A14: Melissa Shandley / 298 Washington Blvd | B14: Eastern Idaho | C14: 2026-09-30 | D14: Commission - Setter | E14: 15189 | F14: 15189 | G14: 759.45
A15: Melissa Shandley / 298 Washington Blvd | B15: Eastern Idaho | C15: 2026-09-30 | D15: Summer bonus - Setter, +2% | E15: 15189 | F15: 15189 | G15: 303.78 | H15: 2 deals set in the week of Sep 27, 2026
A16: Accounts | G16: =SUM(G5:G15) -> 4728.51
A17: Adjustments | G17: =SUMIFS(Adjustments!$D:$D,Adjustments!$A:$A,"Brandon Simpson") -> 0
A18: Paid this run | G18: =G16+G17 -> 4728.51
A19: Held back - not paid
A20: Account | B20: Team | C20: Closed | D20: Leg | E20: Reason | F20: Held since | G20: Placed by | H20: Would have paid in | I20: Withheld
A21: Steven Nelson / 132 Bearlake Dr | B21: Eastern Idaho | C21: 2026-09-04 | D21: Setter | E21: Customer financing not approved | F21: 2026-09-16 | G21: Abipsha Joshi | H21: Sep 18, 2026 | I21: 0

Sheet Shawn Harding
A1: Shawn Harding | B1: Oct 16, 2026 run
A2: Northern Utah - Sales Consultant
A4: Account | B4: Team | C4: Closed | D4: Earned as | E4: Contract value | F4: Paid on | G4: Amount | H4: Note
A5: Timothy Broadbrooks / 3472 Ayden Rd | B5: Northern Utah | C5: 2026-09-14 | D5: Summer bonus - Setter, +4% | E5: 20247 | F5: 20247 | G5: 809.88 | H5: 6 deals set in the week of Sep 13, 2026
A6: Chad Guymon / 3755 Pioneer Park Dr | B6: Northern Utah | C6: 2026-09-15 | D6: Summer bonus - Setter, +4% | E6: 16393 | F6: 16393 | G6: 655.72 | H6: 6 deals set in the week of Sep 13, 2026
A7: Karen O'Donnell / 3216 Harness Loop | B7: Northern Utah | C7: 2026-09-15 | D7: Summer bonus - Setter, +4% | E7: 11229 | F7: 11229 | G7: 449.16 | H7: 6 deals set in the week of Sep 13, 2026
A8: Jennifer Listerud / 3243 Harness Loop | B8: Northern Utah | C8: 2026-09-15 | D8: Summer bonus - Setter, +4% | E8: 5920 | F8: 5920 | G8: 236.8 | H8: 6 deals set in the week of Sep 13, 2026
A9: Jason Brenna / 703 E Riggs St | B9: Northern Utah | C9: 2026-09-17 | D9: Summer bonus - Setter, +4% | E9: 15992 | F9: 15992 | G9: 639.68 | H9: 6 deals set in the week of Sep 13, 2026
A10: Kathy Jacobsen / 3220 Rocky Rd | B10: Northern Utah | C10: 2026-09-18 | D10: Summer bonus - Setter, +4% | E10: 13219 | F10: 13219 | G10: 528.76 | H10: 6 deals set in the week of Sep 13, 2026
A11: Donald Nicholls / 2505 N 6900 W | B11: Northern Utah | C11: 2026-09-30 | D11: Commission - Setter | E11: 9038 | F11: 9038 | G11: 451.9
A12: Corey Anderson / 215 S 300 E | B12: Northern Utah | C12: 2026-10-06 | D12: Commission - Setter | E12: 12418 | F12: 12418 | G12: 620.9
A13: Accounts | G13: =SUM(G5:G12) -> 4392.8
A14: Adjustments | G14: =SUMIFS(Adjustments!$D:$D,Adjustments!$A:$A,"Shawn Harding") -> 0
A15: Paid this run | G15: =G13+G14 -> 4392.8

Sheet Todd Hess
A1: Todd Hess | B1: Oct 16, 2026 run
A2: Northern Utah - Sales Consultant
A4: Account | B4: Team | C4: Closed | D4: Earned as | E4: Contract value | F4: Paid on | G4: Amount | H4: Note
A5: Donald Nicholls / 2505 N 6900 W | B5: Northern Utah | C5: 2026-09-30 | D5: Commission - Closer | E5: 9038 | F5: 9038 | G5: 813.42
A6: Corey Anderson / 215 S 300 E | B6: Northern Utah | C6: 2026-10-06 | D6: Commission - Closer | E6: 12418 | F6: 12418 | G6: 1117.62
A7: Accounts | G7: =SUM(G5:G6) -> 1931.04
A8: Adjustments | G8: =SUMIFS(Adjustments!$D:$D,Adjustments!$A:$A,"Todd Hess") -> 0
A9: Paid this run | G9: =G7+G8 -> 1931.04

Sheet Kimberly Simmerman
A1: Kimberly Simmerman | B1: Oct 16, 2026 run
A2: Southern Utah - Sales Consultant
A4: Account | B4: Team | C4: Closed | D4: Earned as | E4: Contract value | F4: Paid on | G4: Amount | H4: Note
A5: Roger Gold 2 / 12 N Cove Dr | B5: Southern Utah | C5: 2026-09-17 | D5: Summer bonus - Setter, +4% | E5: 20338 | F5: 20338 | G5: 813.52 | H5: 3 deals set in the week of Sep 13, 2026
A6: Carlos & Yanina Becco / 1004 S 860 W | B6: Southern Utah | C6: 2026-09-17 | D6: Summer bonus - Setter, +4% | E6: 20262 | F6: 20262 | G6: 810.48 | H6: 3 deals set in the week of Sep 13, 2026
A7: Marilyn Grainger / 996 S 860 W | B7: Southern Utah | C7: 2026-09-17 | D7: Summer bonus - Setter, +4% | E7: 13193 | F7: 13193 | G7: 527.72 | H7: 3 deals set in the week of Sep 13, 2026
A8: Gauge & Samantha Kevern / 1099 Cedar Knls S | B8: Southern Utah | C8: 2026-10-02 | D8: Commission - Setter | E8: 23395 | F8: 23395 | G8: 1169.75
A9: Accounts | G9: =SUM(G5:G8) -> 3321.47
A10: Adjustments | G10: =SUMIFS(Adjustments!$D:$D,Adjustments!$A:$A,"Kimberly Simmerman") -> 0
A11: Paid this run | G11: =G9+G10 -> 3321.47

Sheet Chase Merrell
A1: Chase Merrell | B1: Oct 16, 2026 run
A2: Southern Utah - Sales Consultant
A4: Account | B4: Team | C4: Closed | D4: Earned as | E4: Contract value | F4: Paid on | G4: Amount | H4: Note
A5: Michael Monday / 192 Quiet Water Ave | B5: Southern Utah | C5: 2026-09-16 | D5: Summer bonus - Setter, +4% | E5: 38023 | F5: 38023 | G5: 1520.92 | H5: 3 deals set in the week of Sep 13, 2026
A6: Jennifer Gaghen / 430 Wigwam Trl | B6: Southern Utah | C6: 2026-09-16 | D6: Summer bonus - Setter, +4% | E6: 18593 | F6: 18593 | G6: 743.72 | H6: 3 deals set in the week of Sep 13, 2026
A7: Steven French / 475 Wigwam Trl | B7: Southern Utah | C7: 2026-09-16 | D7: Summer bonus - Setter, +4% | E7: 9937 | F7: 9937 | G7: 397.48 | H7: 3 deals set in the week of Sep 13, 2026
A8: Accounts | G8: =SUM(G5:G7) -> 2662.12
A9: Adjustments | G9: =SUMIFS(Adjustments!$D:$D,Adjustments!$A:$A,"Chase Merrell") -> 0
A10: Paid this run | G10: =G8+G9 -> 2662.12

Sheet Isabella Basanta
A1: Isabella Basanta | B1: Oct 16, 2026 run
A2: Northern Utah - Sales Consultant
A4: Account | B4: Team | C4: Closed | D4: Earned as | E4: Contract value | F4: Paid on | G4: Amount | H4: Note
A5: Rachel Bond / 4330 Cougar Dr | B5: Northern Utah | C5: 2026-09-15 | D5: Summer bonus - Setter, +4% | E5: 13026 | F5: 13026 | G5: 521.04 | H5: 4 deals set in the week of Sep 13, 2026
A6: Nicholas Hamm / 4432 Red Fox Dr | B6: Northern Utah | C6: 2026-09-16 | D6: Summer bonus - Setter, +4% | E6: 16938 | F6: 16938 | G6: 677.52 | H6: 4 deals set in the week of Sep 13, 2026
A7: Marshall Peterson / 2635 Sundance Dr | B7: Northern Utah | C7: 2026-09-17 | D7: Summer bonus - Setter, +4% | E7: 6121 | F7: 6121 | G7: 244.84 | H7: 4 deals set in the week of Sep 13, 2026
A8: Joshua Fraley / 3825 Remington St | B8: Northern Utah | C8: 2026-09-19 | D8: Summer bonus - Setter, +4% | E8: 19718 | F8: 19718 | G8: 788.72 | H8: 4 deals set in the week of Sep 13, 2026
A9: Mario Ricardo Torres Laboriel / 636 E 300 N | B9: Northern Utah | C9: 2026-09-30 | D9: Commission - Setter | E9: 3534 | F9: 3534 | G9: 176.7
A10: Accounts | G10: =SUM(G5:G9) -> 2408.82
A11: Adjustments | G11: =SUMIFS(Adjustments!$D:$D,Adjustments!$A:$A,"Isabella Basanta") -> 0
A12: Paid this run | G12: =G10+G11 -> 2408.82

Sheet Colter Busk
A1: Colter Busk | B1: Oct 16, 2026 run
A2: Southern Utah - Sales Consultant
A4: Account | B4: Team | C4: Closed | D4: Earned as | E4: Contract value | F4: Paid on | G4: Amount | H4: Note
A5: MARIA PALMER / 11394 E 25th Pl | B5: Southern Utah | C5: 2026-05-30 | D5: Change order - Setter commission | E5: 13422 | F5: 0 | G5: -671.1 | H5: Contract value moved after it was paid
A6: Linda & Dusty McLeod / 2504 Interlachen Dr | B6: Southern Utah | C6: 2026-09-15 | D6: Summer bonus - Setter, +2% | E6: 5841 | F6: 5841 | G6: 116.82 | H6: 2 deals set in the week of Sep 13, 2026
A7: Donald & Nikki Groshans / 2705 Mast Cir | B7: Southern Utah | C7: 2026-09-19 | D7: Summer bonus - Setter, +2% | E7: 12349 | F7: 12349 | G7: 246.98 | H7: 2 deals set in the week of Sep 13, 2026
A8: Brett & Jennie Lefevre / 2817 S 2460 E | B8: Southern Utah | C8: 2026-09-26 | D8: Commission - Setter | E8: 17811 | F8: 17811 | G8: 890.55 | H8: Released from an earlier run
A9: Mical & Elaine Terry / 993 N 2075 East Cir | B9: Southern Utah | C9: 2026-10-01 | D9: Commission - Setter | E9: 14796 | F9: 14796 | G9: 739.8
A10: Accounts | G10: =SUM(G5:G9) -> 1323.05
A11: Adjustments | G11: =SUMIFS(Adjustments!$D:$D,Adjustments!$A:$A,"Colter Busk") -> 0
A12: Paid this run | G12: =G10+G11 -> 1323.05

Sheet Giancarlo Stoffels
A1: Giancarlo Stoffels | B1: Oct 16, 2026 run
A2: Southern Utah - Sales Consultant
A4: Account | B4: Team | C4: Closed | D4: Earned as | E4: Contract value | F4: Paid on | G4: Amount | H4: Note
A5: Darrell & Maggie Phillips / 2220 Pintura Dr | B5: Southern Utah | C5: 2026-09-09 | D5: Commission - Setter | E5: 15902 | F5: 15902 | G5: 795.1 | H5: Released from an earlier run
A6: Tara & Vincent Turpin / 1109 Babcock Blvd | B6: Southern Utah | C6: 2026-10-05 | D6: Commission - Setter | E6: 27179 | F6: 27179 | G6: 1358.95
A7: Accounts | G7: =SUM(G5:G6) -> 2154.05
A8: Adjustments | G8: =SUMIFS(Adjustments!$D:$D,Adjustments!$A:$A,"Giancarlo Stoffels") -> 0
A9: Paid this run | G9: =G7+G8 -> 2154.05

Sheet Zackary Johnston
A1: Zackary Johnston | B1: Oct 16, 2026 run
A2: Eastern Idaho - Sales Consultant
A4: Account | B4: Team | C4: Closed | D4: Earned as | E4: Contract value | F4: Paid on | G4: Amount | H4: Note
A5: Kali Dubose / 213 18th Ave NW | B5: Eastern Idaho | C5: 2026-09-25 | D5: Commission - Setter | E5: 11832 | F5: 11832 | G5: 591.6 | H5: Released from an earlier run
A6: Manuel Fagundes / 67 Embry Ln | B6: Eastern Idaho | C6: 2026-09-27 | D6: Summer bonus - Setter, +2% | E6: 17474 | F6: 17474 | G6: 349.48 | H6: 2 deals set in the week of Sep 27, 2026
A7: Celia & Mike Morse / 237 2nd St NW | B7: Eastern Idaho | C7: 2026-09-28 | D7: Summer bonus - Setter, +2% | E7: 12221 | F7: 12221 | G7: 244.42 | H7: 2 deals set in the week of Sep 27, 2026
A8: Clay Skinner / 297 Westview Dr | B8: Eastern Idaho | C8: 2026-10-06 | D8: Commission - Setter | E8: 12807 | F8: 12807 | G8: 640.35
A9: Accounts | G9: =SUM(G5:G8) -> 1825.85
A10: Adjustments | G10: =SUMIFS(Adjustments!$D:$D,Adjustments!$A:$A,"Zackary Johnston") -> 0
A11: Paid this run | G11: =G9+G10 -> 1825.85

Sheet Kerrigan Simpson
A1: Kerrigan Simpson | B1: Oct 16, 2026 run
A2: Eastern Idaho - Sales Consultant
A4: Account | B4: Team | C4: Closed | D4: Earned as | E4: Contract value | F4: Paid on | G4: Amount | H4: Note
A5: Melissa Shandley / 298 Washington Blvd | B5: Eastern Idaho | C5: 2026-09-30 | D5: Commission - Closer | E5: 15189 | F5: 15189 | G5: 1367.01
A6: Accounts | G6: =SUM(G5:G5) -> 1367.01
A7: Adjustments | G7: =SUMIFS(Adjustments!$D:$D,Adjustments!$A:$A,"Kerrigan Simpson") -> 0
A8: Paid this run | G8: =G6+G7 -> 1367.01
A9: Held back - not paid
A10: Account | B10: Team | C10: Closed | D10: Leg | E10: Reason | F10: Held since | G10: Placed by | H10: Would have paid in | I10: Withheld
A11: Tammy Buckley / 31 Jefferson Dr | B11: Northern Utah | C11: 2026-09-22 | D11: Closer | E11: Customer financing not approved | F11: 2026-09-29 | G11: The CRM | H11: Oct 2, 2026 | I11: 1323.81

Sheet Camille Gerritsen
A1: Camille Gerritsen | B1: Oct 16, 2026 run
A2: Northern Utah - Sales Consultant
A4: Account | B4: Team | C4: Closed | D4: Earned as | E4: Contract value | F4: Paid on | G4: Amount | H4: Note
A5: Phil Bushilla / 701 Red Letter St | B5: Northern Utah | C5: 2026-09-12 | D5: Summer bonus - Setter, +2% | E5: 25904 | F5: 25904 | G5: 518.08 | H5: 2 deals set in the week of Sep 6, 2026
A6: Zoe Bushilla / 2514 Heritage Dr | B6: Northern Utah | C6: 2026-09-12 | D6: Summer bonus - Setter, +2% | E6: 10988 | F6: 10988 | G6: 219.76 | H6: 2 deals set in the week of Sep 6, 2026
A7: Brian Morris / 2102 Turmaline Ct | B7: Northern Utah | C7: 2026-09-14 | D7: Summer bonus - Setter, +2% | E7: 20817 | F7: 20817 | G7: 416.34 | H7: 2 deals set in the week of Sep 13, 2026
A8: Kathleenn Koford / 15 S Raleigh St | B8: Northern Utah | C8: 2026-09-18 | D8: Summer bonus - Setter, +2% | E8: 7448 | F8: 7448 | G8: 148.96 | H8: 2 deals set in the week of Sep 13, 2026
A9: Accounts | G9: =SUM(G5:G8) -> 1303.14
A10: Adjustments | G10: =SUMIFS(Adjustments!$D:$D,Adjustments!$A:$A,"Camille Gerritsen") -> 0
A11: Paid this run | G11: =G9+G10 -> 1303.14
A12: Held back - not paid
A13: Account | B13: Team | C13: Closed | D13: Leg | E13: Reason | F13: Held since | G13: Placed by | H13: Would have paid in | I13: Withheld
A14: Tammy Buckley / 31 Jefferson Dr | B14: Northern Utah | C14: 2026-09-22 | D14: Setter | E14: Customer financing not approved | F14: 2026-09-29 | G14: The CRM | H14: Oct 2, 2026 | I14: 735.45

Sheet Ethan Saxton
A1: Ethan Saxton | B1: Oct 16, 2026 run
A2: Southern Utah - Sales Consultant
A4: Account | B4: Team | C4: Closed | D4: Earned as | E4: Contract value | F4: Paid on | G4: Amount | H4: Note
A5: Maralene Spawn / 1242 Cortez Ave | B5: Southern Utah | C5: 2026-09-14 | D5: Summer bonus - Setter, +2% | E5: 15127 | F5: 15127 | G5: 302.54 | H5: 2 deals set in the week of Sep 13, 2026
A6: Darlene Bohl / 1082 Sierra Granda Blvd | B6: Southern Utah | C6: 2026-09-17 | D6: Summer bonus - Setter, +2% | E6: 9869 | F6: 9869 | G6: 197.38 | H6: 2 deals set in the week of Sep 13, 2026
A7: Accounts | G7: =SUM(G5:G6) -> 499.92
A8: Adjustments | G8: =SUMIFS(Adjustments!$D:$D,Adjustments!$A:$A,"Ethan Saxton") -> 0
A9: Paid this run | G9: =G7+G8 -> 499.92

Sheet Kress Johnson
A1: Kress Johnson | B1: Oct 16, 2026 run
A2: Southern Utah - Sales Consultant
A4: Account | B4: Team | C4: Closed | D4: Earned as | E4: Contract value | F4: Paid on | G4: Amount | H4: Note
A5: Cindy Sahli / 3941 Rimrock Rd | B5: Southern Utah | C5: 2026-09-17 | D5: Summer bonus - Setter, +2% | E5: 25350 | F5: 25350 | G5: 507 | H5: 2 deals set in the week of Sep 13, 2026
A6: Nathan Royer / 4245 Palisades Park Dr | B6: Southern Utah | C6: 2026-09-18 | D6: Summer bonus - Setter, +2% | E6: 31755 | F6: 31755 | G6: 635.1 | H6: 2 deals set in the week of Sep 13, 2026
A7: Accounts | G7: =SUM(G5:G6) -> 1142.1
A8: Adjustments | G8: =SUMIFS(Adjustments!$D:$D,Adjustments!$A:$A,"Kress Johnson") -> 0
A9: Paid this run | G9: =G7+G8 -> 1142.1

Sheet Dane Covington
A1: Dane Covington | B1: Oct 16, 2026 run
A2: Northern Utah - Sales Consultant
A4: Account | B4: Team | C4: Closed | D4: Earned as | E4: Contract value | F4: Paid on | G4: Amount | H4: Note
A5: TRACEY USCOLA / 217 W 5th N | B5: Northern Utah | C5: 2026-03-26 | D5: Change order - Closer commission | E5: 4400 | F5: 4400 | G5: -866.34 | H5: Contract value moved after it was paid
A6: James Burdick / 1902 Wilder Ave | B6: Northern Utah | C6: 2026-09-13 | D6: Summer bonus - Setter, +4% | E6: 4760 | F6: 4760 | G6: 190.4 | H6: 3 deals set in the week of Sep 13, 2026
A7: Mike Bakke / 1122 Choteau St | B7: Northern Utah | C7: 2026-09-14 | D7: Summer bonus - Setter, +4% | E7: 25357 | F7: 25357 | G7: 1014.28 | H7: 3 deals set in the week of Sep 13, 2026
A8: Bryant Gauthier / 1827 Hollins Ave | B8: Northern Utah | C8: 2026-09-19 | D8: Summer bonus - Setter, +4% | E8: 16030 | F8: 16030 | G8: 641.2 | H8: 3 deals set in the week of Sep 13, 2026
A9: Accounts | G9: =SUM(G5:G8) -> 979.54
A10: Adjustments | G10: =SUMIFS(Adjustments!$D:$D,Adjustments!$A:$A,"Dane Covington") -> 0
A11: Paid this run | G11: =G9+G10 -> 979.54

Sheet Diane Oswald
A1: Diane Oswald | B1: Oct 16, 2026 run
A2: Southern Utah - Sales Consultant
A4: Account | B4: Team | C4: Closed | D4: Earned as | E4: Contract value | F4: Paid on | G4: Amount | H4: Note
A5: Lisa & John Matz / 4119 June Dr | B5: Southern Utah | C5: 2026-09-14 | D5: Summer bonus - Setter, +2% | E5: 20226 | F5: 20226 | G5: 404.52 | H5: 2 deals set in the week of Sep 13, 2026
A6: Shawn & Angela Hannah / 551 Tabriz Dr | B6: Southern Utah | C6: 2026-09-15 | D6: Summer bonus - Setter, +2% | E6: 24813 | F6: 24813 | G6: 496.26 | H6: 2 deals set in the week of Sep 13, 2026
A7: Accounts | G7: =SUM(G5:G6) -> 900.78
A8: Adjustments | G8: =SUMIFS(Adjustments!$D:$D,Adjustments!$A:$A,"Diane Oswald") -> 0
A9: Paid this run | G9: =G7+G8 -> 900.78

Sheet Travis Dykman
A1: Travis Dykman | B1: Oct 16, 2026 run
A2: Eastern Idaho - Sales Consultant
A4: Account | B4: Team | C4: Closed | D4: Earned as | E4: Contract value | F4: Paid on | G4: Amount | H4: Note
A5: Joy Hepworth / 131 Willard Ave | B5: Eastern Idaho | C5: 2026-09-10 | D5: Commission - Setter | E5: 12935 | F5: 12935 | G5: 646.75 | H5: Released from an earlier run
A6: Accounts | G6: =SUM(G5:G5) -> 646.75
A7: Adjustments | G7: =SUMIFS(Adjustments!$D:$D,Adjustments!$A:$A,"Travis Dykman") -> 0
A8: Paid this run | G8: =G6+G7 -> 646.75

Sheet Alan Fransen
A1: Alan Fransen | B1: Oct 16, 2026 run
A2: Eastern Idaho - Sales Consultant
A4: Account | B4: Team | C4: Closed | D4: Earned as | E4: Contract value | F4: Paid on | G4: Amount | H4: Note
A5: Forrest Barnes / 237 N 4300 E | B5: Eastern Idaho | C5: 2026-09-24 | D5: Summer bonus - Setter, +2% | E5: 13441 | F5: 13441 | G5: 268.82 | H5: 2 deals set in the week of Sep 20, 2026
A6: Thomas Strong / 4124 E 230 N | B6: Eastern Idaho | C6: 2026-09-24 | D6: Summer bonus - Setter, +2% | E6: 6095 | F6: 6095 | G6: 121.9 | H6: 2 deals set in the week of Sep 20, 2026
A7: Accounts | G7: =SUM(G5:G6) -> 390.72
A8: Adjustments | G8: =SUMIFS(Adjustments!$D:$D,Adjustments!$A:$A,"Alan Fransen") -> 0
A9: Paid this run | G9: =G7+G8 -> 390.72

Sheet Terry Xanthos
A1: Terry Xanthos | B1: Oct 16, 2026 run
A2: Northern Utah - Sales Consultant
A4: Account | B4: Team | C4: Closed | D4: Earned as | E4: Contract value | F4: Paid on | G4: Amount | H4: Note
A5: Mario Ricardo Torres Laboriel / 636 E 300 N | B5: Northern Utah | C5: 2026-09-30 | D5: Commission - Closer | E5: 3534 | F5: 3534 | G5: 318.06
A6: Accounts | G6: =SUM(G5:G5) -> 318.06
A7: Adjustments | G7: =SUMIFS(Adjustments!$D:$D,Adjustments!$A:$A,"Terry Xanthos") -> 0
A8: Paid this run | G8: =G6+G7 -> 318.06

Sheet Lane Coffey
A1: Lane Coffey | B1: Oct 16, 2026 run
A2: Eastern Idaho - Sales Consultant
A4: Account | B4: Team | C4: Closed | D4: Earned as | E4: Contract value | F4: Paid on | G4: Amount | H4: Note
A5: Christine Warner / 121 Dallas St | B5: Eastern Idaho | C5: 2026-09-11 | D5: Summer bonus - Setter, +2% | E5: 17633 | F5: 17633 | G5: 352.66 | H5: 2 deals set in the week of Sep 6, 2026
A6: Dennis Vaillancourt / 212 Pine St | B6: Eastern Idaho | C6: 2026-09-12 | D6: Summer bonus - Setter, +2% | E6: 7519 | F6: 7519 | G6: 150.38 | H6: 2 deals set in the week of Sep 6, 2026
A7: Accounts | G7: =SUM(G5:G6) -> 503.04
A8: Adjustments | G8: =SUMIFS(Adjustments!$D:$D,Adjustments!$A:$A,"Lane Coffey") -> 0
A9: Paid this run | G9: =G7+G8 -> 503.04
A10: Held back - not paid
A11: Account | B11: Team | C11: Closed | D11: Leg | E11: Reason | F11: Held since | G11: Placed by | H11: Would have paid in | I11: Withheld
A12: Matt & Shauna Bevan / 272 Saddle Dr | B12: Eastern Idaho | C12: 2026-10-09 | D12: Setter | E12: Customer financing not approved | F12: 2026-10-15 | G12: The CRM | H12: Oct 23, 2026 | I12: 2033.9

Sheet Blake Holmes
A1: Blake Holmes | B1: Oct 16, 2026 run
A2: Northern Utah - Sales Consultant
A4: Account | B4: Team | C4: Closed | D4: Earned as | E4: Contract value | F4: Paid on | G4: Amount | H4: Note
A5: Accounts | G5: 0
A6: Adjustments | G6: =SUMIFS(Adjustments!$D:$D,Adjustments!$A:$A,"Blake Holmes") -> -412.5
A7: Paid this run | G7: =G5+G6 -> -412.5

Sheet Jonathan Jensen
A1: Jonathan Jensen | B1: Oct 16, 2026 run
A2: Southern Utah - Sales Consultant
A4: Account | B4: Team | C4: Closed | D4: Earned as | E4: Contract value | F4: Paid on | G4: Amount | H4: Note
A5: Amanda Morning Star / 120 Riverview 3 E | B5: Southern Utah | C5: 2026-07-21 | D5: Change order - Summer weekly bonus | E5: 21964 | F5: 0 | G5: -878.56 | H5: Contract value moved after it was paid
A6: Amanda Morning Star / 120 Riverview 3 E | B6: Southern Utah | C6: 2026-07-21 | D6: Change order - Setter commission | E6: 21964 | F6: 0 | G6: -1098.2 | H6: Contract value moved after it was paid
A7: Accounts | G7: =SUM(G5:G6) -> -1976.76
A8: Adjustments | G8: =SUMIFS(Adjustments!$D:$D,Adjustments!$A:$A,"Jonathan Jensen") -> 0
A9: Paid this run | G9: =G7+G8 -> -1976.76
